Workbook
Name Slicer_Return: #N/A
Name Slicer_Sector: #N/A
Name Slicer_Sector1: #N/A
Name Slicer_Stock_Name: #N/A

Sheet Home
G1: 📈 STOCK MARKET PORTFOLIO TRACKER & RETURN ANALYZER

Sheet Dashboard
G2: 📈 STOCK MARKET PORTFOLIO TRACKER & RETURN ANALYZER
G8: Total Market Value | O8: Total Investment | W8: ="Total " & IF($W$11>=0, "Profit", "Loss") -> Total Profit | AE8: Return On Investment
G11: ='My Holdings'!O32 -> 6272596.7 | O11: ='My Holdings'!M32 -> 3533128.6 | W11: ='My Holdings'!P32 -> 2739468.1 | AE11: ='My Holdings'!Q32 -> 0.77536609
G19: Sector Wise Allocation | S19: Investment vs Profit / Loss | AE19: Quantity in Hold
G45: Sector Vs Month
G60: Total Investment Vs Total Market Value Vs Profit/Loss

Sheet Raw Data
F1: 📈 STOCK MARKET PORTFOLIO TRACKER & RETURN ANALYZER
F6: Raw Data
F9: Order_ID | G9: Date | H9: Sector | I9: Stock_Name | J9: Buy_Price | K9: Sell_Price | L9: Quantity | M9: Order_Type | O9: Cleaned_Order_Type | P9: Curr_Hold | Q9: Date_format | R9: Reason_1 | S9: Reason_2 | T9: Reason_3 | U9: Reason_4 | V9: Decision
F10: ORD1076 | G10: 2025-04-09 | H10: Paints | I10: ASIANPAINT | J10: NULL | K10: 2464.09 | L10: 10 | M10: B | O10: =IF(LEFT(UPPER(M10),1)="S","SELL",IF(LEFT(UPPER(M10),1)="B","BUY","INVALID")) -> BUY | P10: =IF(L10 = "NULL", 0, IF(AND(I10=I11, H10=H11), P11 + IF(O10="BUY", L10, -L10), IF(O10="BUY", L10, -L10))) -> 25 | Q10: =DATEVALUE(Table1[[#This Row],[Date]]) -> 45756 | R10: =IF(F10="NULL", "INVALID", "VALID") -> VALID | S10: =IF(R10="VALID", IF(AND(J10="NULL",K10="NULL"), "INVALID", "VALID"), "INVALID") -> VALID | T10: =IF(S10="VALID", IF(P10<0, "INVALID", "VALID"), "INVALID") -> VALID | U10: =IF(T10="VALID", IF(Table1[[#This Row],[Quantity]]="NULL", "INVALID", "VALID"), "INVALID") -> VALID | V10: =IF(U10="VALID", "KEEP","DELETE") -> KEEP
F11: ORD1073 | G11: 2025-03-31 | H11: Paints | I11: ASIANPAINT | J11: 3284.04 | L11: 25 | M11: Buy | O11: =IF(LEFT(UPPER(M11),1)="S","SELL",IF(LEFT(UPPER(M11),1)="B","BUY","INVALID")) -> BUY | P11: =IF(L11 = "NULL", 0, IF(AND(I11=I12, H11=H12), P12 + IF(O11="BUY", L11, -L11), IF(O11="BUY", L11, -L11))) -> 15 | Q11: =DATEVALUE(Table1[[#This Row],[Date]]) -> 45747 | R11: =IF(F11="NULL", "INVALID", "VALID") -> VALID | S11: =IF(R11="VALID", IF(AND(J11="NULL",K11="NULL"), "INVALID", "VALID"), "INVALID") -> VALID | T11: =IF(S11="VALID", IF(P11<0, "INVALID", "VALID"), "INVALID") -> VALID | U11: =IF(T11="VALID", IF(Table1[[#This Row],[Quantity]]="NULL", "INVALID", "VALID"), "INVALID") -> VALID | V11: =IF(U11="VALID", "KEEP","DELETE") -> KEEP
F12: ORD1079 | G12: 2025-03-18 | H12: Paints | I12: ASIANPAINT | J12: NULL | K12: 2494.34 | L12: 10 | M12: SELLA | O12: =IF(LEFT(UPPER(M12),1)="S","SELL",IF(LEFT(UPPER(M12),1)="B","BUY","INVALID")) -> SELL | P12: =IF(L12 = "NULL", 0, IF(AND(I12=I13, H12=H13), P13 + IF(O12="BUY", L12, -L12), IF(O12="BUY", L12, -L12))) -> -10 | Q12: =DATEVALUE(Table1[[#This Row],[Date]]) -> 45734 | R12: =IF(F12="NULL", "INVALID", "VALID") -> VALID | S12: =IF(R12="VALID", IF(AND(J12="NULL",K12="NULL"), "INVALID", "VALID"), "INVALID") -> VALID | T12: =IF(S12="VALID", IF(P12<0, "INVALID", "VALID"), "INVALID") -> INVALID | U12: =IF(T12="VALID", IF(Table1[[#This Row],[Quantity]]="NULL", "INVALID", "VALID"), "INVALID") -> INVALID | V12: =IF(U12="VALID", "KEEP","DELETE") -> DELETE
F13: ORD1166 | G13: 2025-02-18 | H13: Paints | I13: ASIANPAINT | J13: 1920.27 | L13: 50 | M13: BUY | O13: =IF(LEFT(UPPER(M13),1)="S","SELL",IF(LEFT(UPPER(M13),1)="B","BUY","INVALID")) -> BUY | P13: =IF(L13 = "NULL", 0, IF(AND(I13=I14, H13=H14), P14 + IF(O13="BUY", L13, -L13), IF(O13="BUY", L13, -L13))) -> 0 | Q13: =DATEVALUE(Table1[[#This Row],[Date]]) -> 45706 | R13: =IF(F13="NULL", "INVALID", "VALID") -> VALID | S13: =IF(R13="VALID", IF(AND(J13="NULL",K13="NULL"), "INVALID", "VALID"), "INVALID") -> VALID | T13: =IF(S13="VALID", IF(P13<0, "INVALID", "VALID"), "INVALID") -> VALID | U13: =IF(T13="VALID", IF(Table1[[#This Row],[Quantity]]="NULL", "INVALID", "VALID"), "INVALID") -> VALID | V13: =IF(U13="VALID", "KEEP","DELETE") -> KEEP
F14: ORD1005 | G14: 2025-01-27 | H14: Paints | I14: ASIANPAINT | J14: NULL | K14: 649.76 | L14: 50 | M14: SELL | O14: =IF(LEFT(UPPER(M14),1)="S","SELL",IF(LEFT(UPPER(M14),1)="B","BUY","INVALID")) -> SELL | P14: =IF(L14 = "NULL", 0, IF(AND(I14=I15, H14=H15), P15 + IF(O14="BUY", L14, -L14), IF(O14="BUY", L14, -L14))) -> -50 | Q14: =DATEVALUE(Table1[[#This Row],[Date]]) -> 45684 | R14: =IF(F14="NULL", "INVALID", "VALID") -> VALID | S14: =IF(R14="VALID", IF(AND(J14="NULL",K14="NULL"), "INVALID", "VALID"), "INVALID") -> VALID | T14: =IF(S14="VALID", IF(P14<0, "INVALID", "VALID"), "INVALID") -> INVALID | U14: =IF(T14="VALID", IF(Table1[[#This Row],[Quantity]]="NULL", "INVALID", "VALID"), "INVALID") -> INVALID | V14: =IF(U14="VALID", "KEEP","DELETE") -> DELETE
F15: ORD1186 | G15: 2025-06-23 | H15: Banking | I15: AXISBANK | J15: 2282.67 | K15: NULL | L15: 25 | M15: BUY | O15: =IF(LEFT(UPPER(M15),1)="S","SELL",IF(LEFT(UPPER(M15),1)="B","BUY","INVALID")) -> BUY | P15: =IF(L15 = "NULL", 0, IF(AND(I15=I16, H15=H16), P16 + IF(O15="BUY", L15, -L15), IF(O15="BUY", L15, -L15))) -> 50 | Q15: =DATEVALUE(Table1[[#This Row],[Date]]) -> 45831 | R15: =IF(F15="NULL", "INVALID", "VALID") -> VALID | S15: =IF(R15="VALID", IF(AND(J15="NULL",K15="NULL"), "INVALID", "VALID"), "INVALID") -> VALID | T15: =IF(S15="VALID", IF(P15<0, "INVALID", "VALID"), "INVALID") -> VALID | U15: =IF(T15="VALID", IF(Table1[[#This Row],[Quantity]]="NULL", "INVALID", "VALID"), "INVALID") -> VALID | V15: =IF(U15="VALID", "KEEP","DELETE") -> KEEP
F16: ORD1011 | G16: 2025-06-21 | H16: Banking | I16: AXISBANK | J16: 1390.11 | K16: NULL | L16: 20 | M16: BUYY | O16: =IF(LEFT(UPPER(M16),1)="S","SELL",IF(LEFT(UPPER(M16),1)="B","BUY","INVALID")) -> BUY | P16: =IF(L16 = "NULL", 0, IF(AND(I16=I17, H16=H17), P17 + IF(O16="BUY", L16, -L16), IF(O16="BUY", L16, -L16))) -> 25 | Q16: =DATEVALUE(Table1[[#This Row],[Date]]) -> 45829 | R16: =IF(F16="NULL", "INVALID", "VALID") -> VALID | S16: =IF(R16="VALID", IF(AND(J16="NULL",K16="NULL"), "INVALID", "VALID"), "INVALID") -> VALID | T16: =IF(S16="VALID", IF(P16<0, "INVALID", "VALID"), "INVALID") -> VALID | U16: =IF(T16="VALID", IF(Table1[[#This Row],[Quantity]]="NULL", "INVALID", "VALID"), "INVALID") -> VALID | V16: =IF(U16="VALID", "KEEP","DELETE") -> KEEP
F17: ORD1122 | G17: 2025-05-23 | H17: Banking | I17: AXISBANK | J17: NULL | K17: 1228.25 | L17: 25 | M17: SELL | O17: =IF(LEFT(UPPER(M17),1)="S","SELL",IF(LEFT(UPPER(M17),1)="B","BUY","INVALID")) -> SELL | P17: =IF(L17 = "NULL", 0, IF(AND(I17=I18, H17=H18), P18 + IF(O17="BUY", L17, -L17), IF(O17="BUY", L17, -L17))) -> 5 | Q17: =DATEVALUE(Table1[[#This Row],[Date]]) -> 45800 | R17: =IF(F17="NULL", "INVALID", "VALID") -> VALID | S17: =IF(R17="VALID", IF(AND(J17="NULL",K17="NULL"), "INVALID", "VALID"), "INVALID") -> VALID | T17: =IF(S17="VALID", IF(P17<0, "INVALID", "VALID"), "INVALID") -> VALID | U17: =IF(T17="VALID", IF(Table1[[#This Row],[Quantity]]="NULL", "INVALID", "VALID"), "INVALID") -> VALID | V17: =IF(U17="VALID", "KEEP","DELETE") -> KEEP
F18: ORD1177 | G18: 2025-05-16 | H18: Banking | I18: AXISBANK | J18: NULL | K18: 1644.42 | L18: 20 | M18: SELL | O18: =IF(LEFT(UPPER(M18),1)="S","SELL",IF(LEFT(UPPER(M18),1)="B","BUY","INVALID")) -> SELL | P18: =IF(L18 = "NULL", 0, IF(AND(I18=I19, H18=H19), P19 + IF(O18="BUY", L18, -L18), IF(O18="BUY", L18, -L18))) -> 30 | Q18: =DATEVALUE(Table1[[#This Row],[Date]]) -> 45793 | R18: =IF(F18="NULL", "INVALID", "VALID") -> VALID | S18: =IF(R18="VALID", IF(AND(J18="NULL",K18="NULL"), "INVALID", "VALID"), "INVALID") -> VALID | T18: =IF(S18="VALID", IF(P18<0, "INVALID", "VALID"), "INVALID") -> VALID | U18: =IF(T18="VALID", IF(Table1[[#This Row],[Quantity]]="NULL", "INVALID", "VALID"), "INVALID") -> VALID | V18: =IF(U18="VALID", "KEEP","DELETE") -> KEEP
F19: ORD1127 | G19: 2025-04-01 | H19: Banking | I19: AXISBANK | J19: NULL | K19: 3804.69 | L19: 50 | M19: SELL | O19: =IF(LEFT(UPPER(M19),1)="S","SELL",IF(LEFT(UPPER(M19),1)="B","BUY","INVALID")) -> SELL | P19: =IF(L19 = "NULL", 0, IF(AND(I19=I20, H19=H20), P20 + IF(O19="BUY", L19, -L19), IF(O19="BUY", L19, -L19))) -> 50 | Q19: =DATEVALUE(Table1[[#This Row],[Date]]) -> 45748 | R19: =IF(F19="NULL", "INVALID", "VALID") -> VALID | S19: =IF(R19="VALID", IF(AND(J19="NULL",K19="NULL"), "INVALID", "VALID"), "INVALID") -> VALID | T19: =IF(S19="VALID", IF(P19<0, "INVALID", "VALID"), "INVALID") -> VALID | U19: =IF(T19="VALID", IF(Table1[[#This Row],[Quantity]]="NULL", "INVALID", "VALID"), "INVALID") -> VALID | V19: =IF(U19="VALID", "KEEP","DELETE") -> KEEP
F20: ORD1195 | G20: 2025-01-07 | H20: Banking | I20: AXISBANK | J20: 2410.7 | K20: NULL | L20: 100 | M20: BUY | O20: =IF(LEFT(UPPER(M20),1)="S","SELL",IF(LEFT(UPPER(M20),1)="B","BUY","INVALID")) -> BUY | P20: =IF(L20 = "NULL", 0, IF(AND(I20=I21, H20=H21), P21 + IF(O20="BUY", L20, -L20), IF(O20="BUY", L20, -L20))) -> 100 | Q20: =DATEVALUE(Table1[[#This Row],[Date]]) -> 45664 | R20: =IF(F20="NULL", "INVALID", "VALID") -> VALID | S20: =IF(R20="VALID", IF(AND(J20="NULL",K20="NULL"), "INVALID", "VALID"), "INVALID") -> VALID | T20: =IF(S20="VALID", IF(P20<0, "INVALID", "VALID"), "INVALID") -> VALID | U20: =IF(T20="VALID", IF(Table1[[#This Row],[Quantity]]="NULL", "INVALID", "VALID"), "INVALID") -> VALID | V20: =IF(U20="VALID", "KEEP","DELETE") -> KEEP
F21: ORD1022 | G21: 2025-06-24 | H21: Finance | I21: BAJFINANCE | J21: 2428.95 | K21: NULL | L21: 10 | M21: BUY | O21: =IF(LEFT(UPPER(M21),1)="S","SELL",IF(LEFT(UPPER(M21),1)="B","BUY","INVALID")) -> BUY | P21: =IF(L21 = "NULL", 0, IF(AND(I21=I22, H21=H22), P22 + IF(O21="BUY", L21, -L21), IF(O21="BUY", L21, -L21))) -> 280 | Q21: =DATEVALUE(Table1[[#This Row],[Date]]) -> 45832 | R21: =IF(F21="NULL", "INVALID", "VALID") -> VALID | S21: =IF(R21="VALID", IF(AND(J21="NULL",K21="NULL"), "INVALID", "VALID"), "INVALID") -> VALID | T21: =IF(S21="VALID", IF(P21<0, "INVALID", "VALID"), "INVALID") -> VALID | U21: =IF(T21="VALID", IF(Table1[[#This Row],[Quantity]]="NULL", "INVALID", "VALID"), "INVALID") -> VALID | V21: =IF(U21="VALID", "KEEP","DELETE") -> KEEP
F22: ORD1199 | G22: 2025-06-21 | H22: Finance | I22: BAJFINANCE | J22: 1451.96 | K22: NULL | L22: 50 | M22: BUY | O22: =IF(LEFT(UPPER(M22),1)="S","SELL",IF(LEFT(UPPER(M22),1)="B","BUY","INVALID")) -> BUY | P22: =IF(L22 = "NULL", 0, IF(AND(I22=I23, H22=H23), P23 + IF(O22="BUY", L22, -L22), IF(O22="BUY", L22, -L22))) -> 270 | Q22: =DATEVALUE(Table1[[#This Row],[Date]]) -> 45829 | R22: =IF(F22="NULL", "INVALID", "VALID") -> VALID | S22: =IF(R22="VALID", IF(AND(J22="NULL",K22="NULL"), "INVALID", "VALID"), "INVALID") -> VALID | T22: =IF(S22="VALID", IF(P22<0, "INVALID", "VALID"), "INVALID") -> VALID | U22: =IF(T22="VALID", IF(Table1[[#This Row],[Quantity]]="NULL", "INVALID", "VALID"), "INVALID") -> VALID | V22: =IF(U22="VALID", "KEEP","DELETE") -> KEEP
F23: ORD1057 | G23: 2025-06-20 | H23: Finance | I23: BAJFINANCE | J23: NULL | K23: 2448.55 | L23: 5 | M23: SEL | O23: =IF(LEFT(UPPER(M23),1)="S","SELL",IF(LEFT(UPPER(M23),1)="B","BUY","INVALID")) -> SELL | P23: =IF(L23 = "NULL", 0, IF(AND(I23=I24, H23=H24), P24 + IF(O23="BUY", L23, -L23), IF(O23="BUY", L23, -L23))) -> 220 | Q23: =DATEVALUE(Table1[[#This Row],[Date]]) -> 45828 | R23: =IF(F23="NULL", "INVALID", "VALID") -> VALID | S23: =IF(R23="VALID", IF(AND(J23="NULL",K23="NULL"), "INVALID", "VALID"), "INVALID") -> VALID | T23: =IF(S23="VALID", IF(P23<0, "INVALID", "VALID"), "INVALID") -> VALID | U23: =IF(T23="VALID", IF(Table1[[#This Row],[Quantity]]="NULL", "INVALID", "VALID"), "INVALID") -> VALID | V23: =IF(U23="VALID", "KEEP","DELETE") -> KEEP
F24: ORD1078 | G24: 2025-06-20 | H24: Finance | I24: BAJFINANCE | J24: 1370.14 | K24: NULL | L24: 10 | M24: BUY | O24: =IF(LEFT(UPPER(M24),1)="S","SELL",IF(LEFT(UPPER(M24),1)="B","BUY","INVALID")) -> BUY | P24: =IF(L24 = "NULL", 0, IF(AND(I24=I25, H24=H25), P25 + IF(O24="BUY", L24, -L24), IF(O24="BUY", L24, -L24))) -> 225 | Q24: =DATEVALUE(Table1[[#This Row],[Date]]) -> 45828 | R24: =IF(F24="NULL", "INVALID", "VALID") -> VALID | S24: =IF(R24="VALID", IF(AND(J24="NULL",K24="NULL"), "INVALID", "VALID"), "INVALID") -> VALID | T24: =IF(S24="VALID", IF(P24<0, "INVALID", "VALID"), "INVALID") -> VALID | U24: =IF(T24="VALID", IF(Table1[[#This Row],[Quantity]]="NULL", "INVALID", "VALID"), "INVALID") -> VALID | V24: =IF(U24="VALID", "KEEP","DELETE") -> KEEP
F25: ORD1091 | G25: 2025-06-06 | H25: Finance | I25: BAJFINANCE | J25: NULL | K25: 3709.22 | L25: 100 | M25: SELL | O25: =IF(LEFT(UPPER(M25),1)="S","SELL",IF(LEFT(UPPER(M25),1)="B","BUY","INVALID")) -> SELL | P25: =IF(L25 = "NULL", 0, IF(AND(I25=I26, H25=H26), P26 + IF(O25="BUY", L25, -L25), IF(O25="BUY", L25, -L25))) -> 215 | Q25: =DATEVALUE(Table1[[#This Row],[Date]]) -> 45814 | R25: =IF(F25="NULL", "INVALID", "VALID") -> VALID | S25: =IF(R25="VALID", IF(AND(J25="NULL",K25="NULL"), "INVALID", "VALID"), "INVALID") -> VALID | T25: =IF(S25="VALID", IF(P25<0, "INVALID", "VALID"), "INVALID") -> VALID | U25: =IF(T25="VALID", IF(Table1[[#This Row],[Quantity]]="NULL", "INVALID", "VALID"), "INVALID") -> VALID | V25: =IF(U25="VALID", "KEEP","DELETE") -> KEEP
F26: ORD1181 | G26: 2025-05-31 | H26: Finance | I26: BAJFINANCE | J26: 397.44 | K26: NULL | L26: 50 | M26: BUY | O26: =IF(LEFT(UPPER(M26),1)="S","SELL",IF(LEFT(UPPER(M26),1)="B","BUY","INVALID")) -> BUY | P26: =IF(L26 = "NULL", 0, IF(AND(I26=I27, H26=H27), P27 + IF(O26="BUY", L26, -L26), IF(O26="BUY", L26, -L26))) -> 315 | Q26: =DATEVALUE(Table1[[#This Row],[Date]]) -> 45808 | R26: =IF(F26="NULL", "INVALID", "VALID") -> VALID | S26: =IF(R26="VALID", IF(AND(J26="NULL",K26="NULL"), "INVALID", "VALID"), "INVALID") -> VALID | T26: =IF(S26="VALID", IF(P26<0, "INVALID", "VALID"), "INVALID") -> VALID | U26: =IF(T26="VALID", IF(Table1[[#This Row],[Quantity]]="NULL", "INVALID", "VALID"), "INVALID") -> VALID | V26: =IF(U26="VALID", "KEEP","DELETE") -> KEEP
F27: ORD1018 | G27: 2025-05-30 | H27: Finance | I27: BAJFINANCE | J27: NULL | K27: 2731.75 | L27: 75 | M27: SELL | O27: =IF(LEFT(UPPER(M27),1)="S","SELL",IF(LEFT(UPPER(M27),1)="B","BUY","INVALID")) -> SELL | P27: =IF(L27 = "NULL", 0, IF(AND(I27=I28, H27=H28), P28 + IF(O27="BUY", L27, -L27), IF(O27="BUY", L27, -L27))) -> 265 | Q27: =DATEVALUE(Table1[[#This Row],[Date]]) -> 45807 | R27: =IF(F27="NULL", "INVALID", "VALID") -> VALID | S27: =IF(R27="VALID", IF(AND(J27="NULL",K27="NULL"), "INVALID", "VALID"), "INVALID") -> VALID | T27: =IF(S27="VALID", IF(P27<0, "INVALID", "VALID"), "INVALID") -> VALID | U27: =IF(T27="VALID", IF(Table1[[#This Row],[Quantity]]="NULL", "INVALID", "VALID"), "INVALID") -> VALID | V27: =IF(U27="VALID", "KEEP","DELETE") -> KEEP
F28: ORD1008 | G28: 2025-05-28 | H28: Finance | I28: BAJFINANCE | J28: NULL | K28: 2894.7 | L28: 50 | M28: SELL | O28: =IF(LEFT(UPPER(M28),1)="S","SELL",IF(LEFT(UPPER(M28),1)="B","BUY","INVALID")) -> SELL | P28: =IF(L28 = "NULL", 0, IF(AND(I28=I29, H28=H29), P29 + IF(O28="BUY", L28, -L28), IF(O28="BUY", L28, -L28))) -> 340 | Q28: =DATEVALUE(Table1[[#This Row],[Date]]) -> 45805 | R28: =IF(F28="NULL", "INVALID", "VALID") -> VALID | S28: =IF(R28="VALID", IF(AND(J28="NULL",K28="NULL"), "INVALID", "VALID"), "INVALID") -> VALID | T28: =IF(S28="VALID", IF(P28<0, "INVALID", "VALID"), "INVALID") -> VALID | U28: =IF(T28="VALID", IF(Table1[[#This Row],[Quantity]]="NULL", "INVALID", "VALID"), "INVALID") -> VALID | V28: =IF(U28="VALID", "KEEP","DELETE") -> KEEP
F29: ORD1030 | G29: 2025-05-21 | H29: Finance | I29: BAJFINANCE | J29: 580.11 | K29: NULL | L29: 100 | M29: BUY | O29: =IF(LEFT(UPPER(M29),1)="S","SELL",IF(LEFT(UPPER(M29),1)="B","BUY","INVALID")) -> BUY | P29: =IF(L29 = "NULL", 0, IF(AND(I29=I30, H29=H30), P30 + IF(O29="BUY", L29, -L29), IF(O29="BUY", L29, -L29))) -> 390 | Q29: =DATEVALUE(Table1[[#This Row],[Date]]) -> 45798 | R29: =IF(F29="NULL", "INVALID", "VALID") -> VALID | S29: =IF(R29="VALID", IF(AND(J29="NULL",K29="NULL"), "INVALID", "VALID"), "INVALID") -> VALID | T29: =IF(S29="VALID", IF(P29<0, "INVALID", "VALID"), "INVALID") -> VALID | U29: =IF(T29="VALID", IF(Table1[[#This Row],[Quantity]]="NULL", "INVALID", "VALID"), "INVALID") -> VALID | V29: =IF(U29="VALID", "KEEP","DELETE") -> KEEP
F30: ORD1116 | G30: 2025-05-10 | H30: Finance | I30: BAJFINANCE | J30: NULL | K30: 2554.22 | L30: 10 | M30: SELL | O30: =IF(LEFT(UPPER(M30),1)="S","SELL",IF(LEFT(UPPER(M30),1)="B","BUY","INVALID")) -> SELL | P30: =IF(L30 = "NULL", 0, IF(AND(I30=I31, H30=H31), P31 + IF(O30="BUY", L30, -L30), IF(O30="BUY", L30, -L30))) -> 290 | Q30: =DATEVALUE(Table1[[#This Row],[Date]]) -> 45787 | R30: =IF(F30="NULL", "INVALID", "VALID") -> VALID | S30: =IF(R30="VALID", IF(AND(J30="NULL",K30="NULL"), "INVALID", "VALID"), "INVALID") -> VALID | T30: =IF(S30="VALID", IF(P30<0, "INVALID", "VALID"), "INVALID") -> VALID | U30: =IF(T30="VALID", IF(Table1[[#This Row],[Quantity]]="NULL", "INVALID", "VALID"), "INVALID") -> VALID | V30: =IF(U30="VALID", "KEEP","DELETE") -> KEEP
F31: ORD1124 | G31: 2025-04-25 | H31: Finance | I31: BAJFINANCE | J31: 2463.54 | K31: NULL | L31: 100 | M31: buy | O31: =IF(LEFT(UPPER(M31),1)="S","SELL",IF(LEFT(UPPER(M31),1)="B","BUY","INVALID")) -> BUY | P31: =IF(L31 = "NULL", 0, IF(AND(I31=I32, H31=H32), P32 + IF(O31="BUY", L31, -L31), IF(O31="BUY", L31, -L31))) -> 300 | Q31: =DATEVALUE(Table1[[#This Row],[Date]]) -> 45772 | R31: =IF(F31="NULL", "INVALID", "VALID") -> VALID | S31: =IF(R31="VALID", IF(AND(J31="NULL",K31="NULL"), "INVALID", "VALID"), "INVALID") -> VALID | T31: =IF(S31="VALID", IF(P31<0, "INVALID", "VALID"), "INVALID") -> VALID | U31: =IF(T31="VALID", IF(Table1[[#This Row],[Quantity]]="NULL", "INVALID", "VALID"), "INVALID") -> VALID | V31: =IF(U31="VALID", "KEEP","DELETE") -> KEEP
F32: ORD1101 | G32: 2025-04-22 | H32: Finance | I32: BAJFINANCE | J32: 1785.57 | K32: NULL | L32: 25 | M32: BUY | O32: =IF(LEFT(UPPER(M32),1)="S","SELL",IF(LEFT(UPPER(M32),1)="B","BUY","INVALID")) -> BUY | P32: =IF(L32 = "NULL", 0, IF(AND(I32=I33, H32=H33), P33 + IF(O32="BUY", L32, -L32), IF(O32="BUY", L32, -L32))) -> 200 | Q32: =DATEVALUE(Table1[[#This Row],[Date]]) -> 45769 | R32: =IF(F32="NULL", "INVALID", "VALID") -> VALID | S32: =IF(R32="VALID", IF(AND(J32="NULL",K32="NULL"), "INVALID", "VALID"), "INVALID") -> VALID | T32: =IF(S32="VALID", IF(P32<0, "INVALID", "VALID"), "INVALID") -> VALID | U32: =IF(T32="VALID", IF(Table1[[#This Row],[Quantity]]="NULL", "INVALID", "VALID"), "INVALID") -> VALID | V32: =IF(U32="VALID", "KEEP","DELETE") -> KEEP
F33: ORD1098 | G33: 2025-04-18 | H33: Finance | I33: BAJFINANCE | J33: NULL | K33: 1585.88 | L33: 20 | M33: Sell | O33: =IF(LEFT(UPPER(M33),1)="S","SELL",IF(LEFT(UPPER(M33),1)="B","BUY","INVALID")) -> SELL | P33: =IF(L33 = "NULL", 0, IF(AND(I33=I34, H33=H34), P34 + IF(O33="BUY", L33, -L33), IF(O33="BUY", L33, -L33))) -> 175 | Q33: =DATEVALUE(Table1[[#This Row],[Date]]) -> 45765 | R33: =IF(F33="NULL", "INVALID", "VALID") -> VALID | S33: =IF(R33="VALID", IF(AND(J33="NULL",K33="NULL"), "INVALID", "VALID"), "INVALID") -> VALID | T33: =IF(S33="VALID", IF(P33<0, "INVALID", "VALID"), "INVALID") -> VALID | U33: =IF(T33="VALID", IF(Table1[[#This Row],[Quantity]]="NULL", "INVALID", "VALID"), "INVALID") -> VALID | V33: =IF(U33="VALID", "KEEP","DELETE") -> KEEP
F34: ORD1055 | G34: 2025-03-31 | H34: Finance | I34: BAJFINANCE | J34: 1844.71 | K34: NULL | L34: 15 | M34: BUY | O34: =IF(LEFT(UPPER(M34),1)="S","SELL",IF(LEFT(UPPER(M34),1)="B","BUY","INVALID")) -> BUY | P34: =IF(L34 = "NULL", 0, IF(AND(I34=I35, H34=H35), P35 + IF(O34="BUY", L34, -L34), IF(O34="BUY", L34, -L34))) -> 195 | Q34: =DATEVALUE(Table1[[#This Row],[Date]]) -> 45747 | R34: =IF(F34="NULL", "INVALID", "VALID") -> VALID | S34: =IF(R34="VALID", IF(AND(J34="NULL",K34="NULL"), "INVALID", "VALID"), "INVALID") -> VALID | T34: =IF(S34="VALID", IF(P34<0, "INVALID", "VALID"), "INVALID") -> VALID | U34: =IF(T34="VALID", IF(Table1[[#This Row],[Quantity]]="NULL", "INVALID", "VALID"), "INVALID") -> VALID | V34: =IF(U34="VALID", "KEEP","DELETE") -> KEEP
F35: ORD1119 | G35: 2025-03-24 | H35: Finance | I35: BAJFINANCE | J35: NULL | K35: 1912.79 | L35: 25 | M35: SELL | O35: =IF(LEFT(UPPER(M35),1)="S","SELL",IF(LEFT(UPPER(M35),1)="B","BUY","INVALID")) -> SELL | P35: =IF(L35 = "NULL", 0, IF(AND(I35=I36, H35=H36), P36 + IF(O35="BUY", L35, -L35), IF(O35="BUY", L35, -L35))) -> 180 | Q35: =DATEVALUE(Table1[[#This Row],[Date]]) -> 45740 | R35: =IF(F35="NULL", "INVALID", "VALID") -> VALID | S35: =IF(R35="VALID", IF(AND(J35="NULL",K35="NULL"), "INVALID", "VALID"), "INVALID") -> VALID | T35: =IF(S35="VALID", IF(P35<0, "INVALID", "VALID"), "INVALID") -> VALID | U35: =IF(T35="VALID", IF(Table1[[#This Row],[Quantity]]="NULL", "INVALID", "VALID"), "INVALID") -> VALID | V35: =IF(U35="VALID", "KEEP","DELETE") -> KEEP
F36: ORD1129 | G36: 2025-03-12 | H36: Finance | I36: BAJFINANCE | J36: 791.66 | K36: NULL | L36: 100 | M36: BUY | O36: =IF(LEFT(UPPER(M36),1)="S","SELL",IF(LEFT(UPPER(M36),1)="B","BUY","INVALID")) -> BUY | P36: =IF(L36 = "NULL", 0, IF(AND(I36=I37, H36=H37), P37 + IF(O36="BUY", L36, -L36), IF(O36="BUY", L36, -L36))) -> 205 | Q36: =DATEVALUE(Table1[[#This Row],[Date]]) -> 45728 | R36: =IF(F36="NULL", "INVALID", "VALID") -> VALID | S36: =IF(R36="VALID", IF(AND(J36="NULL",K36="NULL"), "INVALID", "VALID"), "INVALID") -> VALID | T36: =IF(S36="VALID", IF(P36<0, "INVALID", "VALID"), "INVALID") -> VALID | U36: =IF(T36="VALID", IF(Table1[[#This Row],[Quantity]]="NULL", "INVALID", "VALID"), "INVALID") -> VALID | V36: =IF(U36="VALID", "KEEP","DELETE") -> KEEP
F37: ORD1037 | G37: 2025-03-04 | H37: Finance | I37: BAJFINANCE | J37: 2573.23 | K37: NULL | L37: 100 | M37: BUY | O37: =IF(LEFT(UPPER(M37),1)="S","SELL",IF(LEFT(UPPER(M37),1)="B","BUY","INVALID")) -> BUY | P37: =IF(L37 = "NULL", 0, IF(AND(I37=I38, H37=H38), P38 + IF(O37="BUY", L37, -L37), IF(O37="BUY", L37, -L37))) -> 105 | Q37: =DATEVALUE(Table1[[#This Row],[Date]]) -> 45720 | R37: =IF(F37="NULL", "INVALID", "VALID") -> VALID | S37: =IF(R37="VALID", IF(AND(J37="NULL",K37="NULL"), "INVALID", "VALID"), "INVALID") -> VALID | T37: =IF(S37="VALID", IF(P37<0, "INVALID", "VALID"), "INVALID") -> VALID | U37: =IF(T37="VALID", IF(Table1[[#This Row],[Quantity]]="NULL", "INVALID", "VALID"), "INVALID") -> VALID | V37: =IF(U37="VALID", "KEEP","DELETE") -> KEEP
F38: ORD1014 | G38: 2025-02-28 | H38: Finance | I38: BAJFINANCE | J38: 2443.46 | K38: NULL | L38: 5 | M38: BUY | O38: =IF(LEFT(UPPER(M38),1)="S","SELL",IF(LEFT(UPPER(M38),1)="B","BUY","INVALID")) -> BUY | P38: =IF(L38 = "NULL", 0, IF(AND(I38=I39, H38=H39), P39 + IF(O38="BUY", L38, -L38), IF(O38="BUY", L38, -L38))) -> 5 | Q38: =DATEVALUE(Table1[[#This Row],[Date]]) -> 45716 | R38: =IF(F38="NULL", "INVALID", "VALID") -> VALID | S38: =IF(R38="VALID", IF(AND(J38="NULL",K38="NULL"), "INVALID", "VALID"), "INVALID") -> VALID | T38: =IF(S38="VALID", IF(P38<0, "INVALID", "VALID"), "INVALID") -> VALID | U38: =IF(T38="VALID", IF(Table1[[#This Row],[Quantity]]="NULL", "INVALID", "VALID"), "INVALID") -> VALID | V38: =IF(U38="VALID", "KEEP","DELETE") -> KEEP
F39: ORD1190 | G39: 2025-02-12 | H39: Finance | I39: BAJFINANCE | J39: NULL | K39: 1931.04 | L39: 25 | M39: SELL | O39: =IF(LEFT(UPPER(M39),1)="S","SELL",IF(LEFT(UPPER(M39),1)="B","BUY","INVALID")) -> SELL | P39: =IF(L39 = "NULL", 0, IF(AND(I39=I40, H39=H40), P40 + IF(O39="BUY", L39, -L39), IF(O39="BUY", L39, -L39))) -> 0 | Q39: =DATEVALUE(Table1[[#This Row],[Date]]) -> 45700 | R39: =IF(F39="NULL", "INVALID", "VALID") -> VALID | S39: =IF(R39="VALID", IF(AND(J39="NULL",K39="NULL"), "INVALID", "VALID"), "INVALID") -> VALID | T39: =IF(S39="VALID", IF(P39<0, "INVALID", "VALID"), "INVALID") -> VALID | U39: =IF(T39="VALID", IF(Table1[[#This Row],[Quantity]]="NULL", "INVALID", "VALID"), "INVALID") -> VALID | V39: =IF(U39="VALID", "KEEP","DELETE") -> KEEP
F40: ORD1023 | G40: 2025-01-29 | H40: Finance | I40: BAJFINANCE | J40: NULL | K40: 2748.51 | L40: 50 | M40: SELL | O40: =IF(LEFT(UPPER(M40),1)="S","SELL",IF(LEFT(UPPER(M40),1)="B","BUY","INVALID")) -> SELL | P40: =IF(L40 = "NULL", 0, IF(AND(I40=I41, H40=H41), P41 + IF(O40="BUY", L40, -L40), IF(O40="BUY", L40, -L40))) -> 25 | Q40: =DATEVALUE(Table1[[#This Row],[Date]]) -> 45686 | R40: =IF(F40="NULL", "INVALID", "VALID") -> VALID | S40: =IF(R40="VALID", IF(AND(J40="NULL",K40="NULL"), "INVALID", "VALID"), "INVALID") -> VALID | T40: =IF(S40="VALID", IF(P40<0, "INVALID", "VALID"), "INVALID") -> VALID | U40: =IF(T40="VALID", IF(Table1[[#This Row],[Quantity]]="NULL", "INVALID", "VALID"), "INVALID") -> VALID | V40: =IF(U40="VALID", "KEEP","DELETE") -> KEEP
F41: ORD1007 | G41: 2025-01-21 | H41: Finance | I41: BAJFINANCE | J41: 3409.94 | K41: NULL | L41: 75 | M41: BUY | O41: =IF(LEFT(UPPER(M41),1)="S","SELL",IF(LEFT(UPPER(M41),1)="B","BUY","INVALID")) -> BUY | P41: =IF(L41 = "NULL", 0, IF(AND(I41=I42, H41=H42), P42 + IF(O41="BUY", L41, -L41), IF(O41="BUY", L41, -L41))) -> 75 | Q41: =DATEVALUE(Table1[[#This Row],[Date]]) -> 45678 | R41: =IF(F41="NULL", "INVALID", "VALID") -> VALID | S41: =IF(R41="VALID", IF(AND(J41="NULL",K41="NULL"), "INVALID", "VALID"), "INVALID") -> VALID | T41: =IF(S41="VALID", IF(P41<0, "INVALID", "VALID"), "INVALID") -> VALID | U41: =IF(T41="VALID", IF(Table1[[#This Row],[Quantity]]="NULL", "INVALID", "VALID"), "INVALID") -> VALID | V41: =IF(U41="VALID", "KEEP","DELETE") -> KEEP
F42: ORD1123 | G42: 2025-05-06 | H42: Telecom | I42: BHARTIARTL | J42: 958.54 | K42: NULL | L42: 75 | M42: BUY | O42: =IF(LEFT(UPPER(M42),1)="S","SELL",IF(LEFT(UPPER(M42),1)="B","BUY","INVALID")) -> BUY | P42: =IF(L42 = "NULL", 0, IF(AND(I42=I43, H42=H43), P43 + IF(O42="BUY", L42, -L42), IF(O42="BUY", L42, -L42))) -> -145 | Q42: =DATEVALUE(Table1[[#This Row],[Date]]) -> 45783 | R42: =IF(F42="NULL", "INVALID", "VALID") -> VALID | S42: =IF(R42="VALID", IF(AND(J42="NULL",K42="NULL"), "INVALID", "VALID"), "INVALID") -> VALID | T42: =IF(S42="VALID", IF(P42<0, "INVALID", "VALID"), "INVALID") -> INVALID | U42: =IF(T42="VALID", IF(Table1[[#This Row],[Quantity]]="NULL", "INVALID", "VALID"), "INVALID") -> INVALID | V42: =IF(U42="VALID", "KEEP","DELETE") -> DELETE
F43: ORD1086 | G43: 2025-05-02 | H43: Telecom | I43: BHARTIARTL | J43: 231.83 | K43: NULL | L43: 20 | M43: BUY | O43: =IF(LEFT(UPPER(M43),1)="S","SELL",IF(LEFT(UPPER(M43),1)="B","BUY","INVALID")) -> BUY | P43: =IF(L43 = "NULL", 0, IF(AND(I43=I44, H43=H44), P44 + IF(O43="BUY", L43, -L43), IF(O43="BUY", L43, -L43))) -> -220 | Q43: =DATEVALUE(Table1[[#This Row],[Date]]) -> 45779 | R43: =IF(F43="NULL", "INVALID", "VALID") -> VALID | S43: =IF(R43="VALID", IF(AND(J43="NULL",K43="NULL"), "INVALID", "VALID"), "INVALID") -> VALID | T43: =IF(S43="VALID", IF(P43<0, "INVALID", "VALID"), "INVALID") -> INVALID | U43: =IF(T43="VALID", IF(Table1[[#This Row],[Quantity]]="NULL", "INVALID", "VALID"), "INVALID") -> INVALID | V43: =IF(U43="VALID", "KEEP","DELETE") -> DELETE
F44: ORD1032 | G44: 2025-04-23 | H44: Telecom | I44: BHARTIARTL | J44: NULL | K44: 1679.77 | L44: 50 | M44: SELL | O44: =IF(LEFT(UPPER(M44),1)="S","SELL",IF(LEFT(UPPER(M44),1)="B","BUY","INVALID")) -> SELL | P44: =IF(L44 = "NULL", 0, IF(AND(I44=I45, H44=H45), P45 + IF(O44="BUY", L44, -L44), IF(O44="BUY", L44, -L44))) -> -240 | Q44: =DATEVALUE(Table1[[#This Row],[Date]]) -> 45770 | R44: =IF(F44="NULL", "INVALID", "VALID") -> VALID | S44: =IF(R44="VALID", IF(AND(J44="NULL",K44="NULL"), "INVALID", "VALID"), "INVALID") -> VALID | T44: =IF(S44="VALID", IF(P44<0, "INVALID", "VALID"), "INVALID") -> INVALID | U44: =IF(T44="VALID", IF(Table1[[#This Row],[Quantity]]="NULL", "INVALID", "VALID"), "INVALID") -> INVALID | V44: =IF(U44="VALID", "KEEP","DELETE") -> DELETE
F45: ORD1047 | G45: 2025-03-22 | H45: Telecom | I45: BHARTIARTL | J45: 2090.25 | K45: NULL | L45: 5 | M45: BUY | O45: =IF(LEFT(UPPER(M45),1)="S","SELL",IF(LEFT(UPPER(M45),1)="B","BUY","INVALID")) -> BUY | P45: =IF(L45 = "NULL", 0, IF(AND(I45=I46, H45=H46), P46 + IF(O45="BUY", L45, -L45), IF(O45="BUY", L45, -L45))) -> -190 | Q45: =DATEVALUE(Table1[[#This Row],[Date]]) -> 45738 | R45: =IF(F45="NULL", "INVALID", "VALID") -> VALID | S45: =IF(R45="VALID", IF(AND(J45="NULL",K45="NULL"), "INVALID", "VALID"), "INVALID") -> VALID | T45: =IF(S45="VALID", IF(P45<0, "INVALID", "VALID"), "INVALID") -> INVALID | U45: =IF(T45="VALID", IF(Table1[[#This Row],[Quantity]]="NULL", "INVALID", "VALID"), "INVALID") -> INVALID | V45: =IF(U45="VALID", "KEEP","DELETE") -> DELETE
F46: ORD1106 | G46: 2025-03-13 | H46: Telecom | I46: BHARTIARTL | J46: NULL | K46: 1369.93 | L46: 75 | M46: SELL | O46: =IF(LEFT(UPPER(M46),1)="S","SELL",IF(LEFT(UPPER(M46),1)="B","BUY","INVALID")) -> SELL | P46: =IF(L46 = "NULL", 0, IF(AND(I46=I47, H46=H47), P47 + IF(O46="BUY", L46, -L46), IF(O46="BUY", L46, -L46))) -> -195 | Q46: =DATEVALUE(Table1[[#This Row],[Date]]) -> 45729 | R46: =IF(F46="NULL", "INVALID", "VALID") -> VALID | S46: =IF(R46="VALID", IF(AND(J46="NULL",K46="NULL"), "INVALID", "VALID"), "INVALID") -> VALID | T46: =IF(S46="VALID", IF(P46<0, "INVALID", "VALID"), "INVALID") -> INVALID | U46: =IF(T46="VALID", IF(Table1[[#This Row],[Quantity]]="NULL", "INVALID", "VALID"), "INVALID") -> INVALID | V46: =IF(U46="VALID", "KEEP","DELETE") -> DELETE
...

Sheet Data Cleaning Process
G1: 📈 STOCK MARKET PORTFOLIO TRACKER & RETURN ANALYZER
H11: DATASET OVERVIEW
H12: Metric | I12: Detail / Value | M12: Notes
H13: Source Sheet | I13: Raw Order_List | M13: Original unprocessed trading order records
H14: Output Sheet | I14: Cleaned_Order_List | M14: Validated, clean records ready for analysis
H15: Raw Total Rows | I15: 203 data rows (excl. header) | M15: All orders before any cleaning applied
H16: Cleaned Rows Retained | I16: 137 rows (KEEP decision) | M16: 54 rows removed via DELETE; some rows fully filtered
H17: Stocks Covered | I17: 21 stocks across 13 sectors | M17: ASIANPAINT, AXISBANK, BAJFINANCE … WIPRO etc.
H18: Raw Columns (Input) | I18: Order_ID · Date · Sector · Stock_Name Buy_Price · Sell_Price · Quantity · Order_Type | M18: 8 core input columns
H19: Helper Columns Added (Raw Sheet) | I19: Cleaned_Order_Type · Curr_Hold · Date_format Reason_1 · Reason_2 · Reason_3 · Reason_4 · Decision | M19: 8 columns documenting every cleaning decision
H20: Cleaned Output Columns | I20: Order_ID · Date · Sector · Stock_Name · Buy_Price Sell_Price · Quantity · Order_Type · Curr_holding · BP*Qty | M20: 10 final columns incl. 2 newly derived
H23: RAW DATA QUALITY ISSUES IDENTIFIED
H24: Sl No | I24: Issue / Problem | J24: Description & Real Examples from Data | M24: Column(s)
H25: 1 | I25: Misspelled / Inconsistent Order Types | J25: Order_Type contained 12+ non-standard variants instead of clean BUY/SELL: "B" (ORD1076) · "Buy" (ORD1073) · "BUYY" (ORD1011) · "buy" (ORD1124) "BuY" (ORD1191) · "Bub" (ORD1135) · "by" (ORD1169) "SEL" (ORD1057) · "Sell" (ORD1098) · "SELLA" (ORD1079) · "Sl" (ORD1141) · "sale" (ORD1120) | K25: Order_Type | L25: 12 variants | M25: Cleaned_ Order_Type
H26: 2 | I26: "NULL" Text Strings in Price Columns | J26: Buy_Price and/or Sell_Price stored as the literal text "NULL" rather than a blank. Makes numeric operations (SUM, AVG, VLOOKUP) fail completely. Expected: BUY orders → Buy_Price numeric, Sell_Price blank (and vice-versa). | K26: Buy_Price Sell_Price | L26: 94 Buy NULLs 106 Sell NULLs | M26: Reason_2
H27: 3 | I27: Both Prices Missing Simultaneously | J27: Three specific rows had "NULL" in BOTH Buy_Price AND Sell_Price: ORD1148 (MARUTI · SELL · Qty 80) NULL Order_ID (Finance · SELL · Qty 20) NULL Order_ID (SUNPHARMA · buy · Qty NULL) Record is financially meaningless without any price. | K27: Buy_Price & Sell_Price | L27: 3 rows | M27: Reason_2 → INVALID
H28: 4 | I28: Date Stored as Plain Text String | J28: All Date values stored as text strings e.g. "2025-04-09" instead of proper Excel date serial numbers. Prevents date arithmetic, chronological sorting, and timeline-based analysis. Converted values stored in new Date_format column as datetime objects. | K28: Date | L28: All 203 rows | M28: Date_format column
H29: 5 | I29: Negative Cumulative Holdings (Oversell) | J29: Curr_Hold tracks running cumulative quantity per stock (date-ordered). When a SELL makes Curr_Hold < 0, it means selling shares never purchased. Examples: ORD1079 (ASIANPAINT → −10) · ORD1005 (ASIANPAINT → −50) All 9 BHARTIARTL orders · All 11 HDFCBANK orders become negative. | K29: Derived: Curr_Hold | L29: 53 rows | M29: Reason_3 → INVALID
H30: 6 | I30: Missing / NULL Order_ID | J30: Two rows had Order_ID = "NULL" — completely untraceable, unauditable orders. One NULL row also had NULL Stock_Name; another was for SUNPHARMA. | K30: Order_ID | L30: 2 rows | M30: Reason_1 → INVALID
H31: 7 | I31: Missing Quantity | J31: One row (NULL Order_ID · SUNPHARMA · "buy") had Quantity = "NULL". Cannot calculate position size, trade value, or holdings without quantity. | K31: Quantity | L31: 1 row | M31: Reason_4 → INVALID
H35: 3 › STEP-BY-STEP CLEANING PROCESS APPLIED
H36: Step | I36: Action Taken | J36: Rule / Logic Applied | L36: Raw Value (Before) | M36: Clean Value (After) | N36: Helper Column
H37: 1 | I37: Standardise Order Type | J37: All Order_Type variants mapped to canonical BUY or SELL using case-insensitive pattern matching: "B","Buy","buy","BuY","Bub","BUYY","by" → BUY "Sell","SEL","SELLA","Sl","sale" → SELL Result stored in Cleaned_Order_Type column (raw value preserved). | L37: "B","BUYY","by" "SEL","Sl","sale" | M37: "BUY" or "SELL" (uniform uppercase) | N37: Cleaned_Order_Type "Resolved Mistyped Values"
H38: 2 | I38: Replace NULL Strings with Blank Cells | J38: Text "NULL" in Buy_Price / Sell_Price replaced with empty cells. BUY orders → Buy_Price = numeric value, Sell_Price = blank SELL orders → Sell_Price = numeric value, Buy_Price = blank Enables numeric formulas, aggregations and filters to function. | L38: Buy_Price = "NULL" or Sell_Price = "NULL" | M38: Blank cell or actual numeric price value | N38: — (applied in-place in price columns)
H39: 3 | I39: Convert Date Text to Excel Date Format | J39: Date column stored as plain text strings ("2025-04-09"). Converted to proper Excel datetime serial values via DATEVALUE(). Enables chronological sorting, date filtering, day-count arithmetic. Stored in Date_format column; used in Cleaned sheet. | L39: "2025-04-09" (text string) | M39: datetime(2025,4,9) = serial 45756 = Apr 09 2025 | N39: Date_format "Converted text to Actual Date format"
H40: 4 | I40: Flag Missing Order_ID (Reason_1) | J40: Check: IF Order_ID = "NULL" OR blank → Reason_1 = "INVALID" Else → Reason_1 = "VALID" Orders without an ID are untraceable and unauditable. | L40: Order_ID = "NULL" or blank | M40: Reason_1 = "INVALID" → Decision = DELETE | N40: Reason_1 "Order_ID Missing"
H41: 5 | I41: Flag Both-Prices- Missing (Reason_2) | J41: Check: IF Buy_Price = "NULL" AND Sell_Price = "NULL" → Reason_2 = "INVALID" A record with no price data has zero financial value. Single-price missing is acceptable (BUY has Buy_Price, SELL has Sell_Price). | L41: Buy_Price="NULL" AND Sell_Price="NULL" | M41: Reason_2 = "INVALID" → Decision = DELETE | N41: Reason_2 "Both Buy_Price & Sell_Price Missing"
H42: 6 | I42: Flag Oversell / Negative Holdings (Reason_3) | J42: Curr_Hold = running cumulative Quantity per stock (date-ascending order): +Qty for BUY orders, −Qty for SELL orders IF Curr_Hold < 0 → Reason_3 = "INVALID" (selling shares never owned) E.g. BHARTIARTL and HDFCBANK had negative holdings from the very first trade. | L42: SELL reduces Curr_Hold below 0 | M42: Reason_3 = "INVALID" → Decision = DELETE | N42: Reason_3 "Cannot SELL before BUYING"
H43: 7 | I43: Flag Missing Quantity (Reason_4) | J43: Check: IF Quantity = "NULL" OR blank → Reason_4 = "INVALID" Without quantity, position size, trade value (BP*Qty), and Curr_Hold cannot be computed. NOTE: Reason_4 co-fires with Reason_3 on all 54 delete rows (cascade effect — negative holding also implies qty problem). | L43: Quantity = "NULL" or blank | M43: Reason_4 = "INVALID" → Decision = DELETE | N43: Reason_4 "Quantity Missing"
H44: 8 | I44: Apply Final Decision & Build Cleaned Sheet | J44: Decision = "KEEP" if ALL of Reason_1–4 = "VALID" Decision = "DELETE" if ANY Reason = "INVALID" KEEP rows copied to Cleaned_Order_List sheet. Two new columns added in cleaned sheet: • Curr_holding — recalculated cumulative qty on clean rows only • BP*Qty — Buy_Price × Quantity (trade cost value for BUY orders) | L44: 203 raw records with quality issues present | M44: 137 clean records with BP*Qty added | N44: Decision (KEEP / DELETE)
H49: VALIDATION RULE MATRIX — Reason Columns & Decision Logic
H50: Reason Col | I50: Checks For | J50: "VALID" Condition | L50: "INVALID" Condition | M50: Rows Flagged | N50: Impact on Decision
H51: Reason_1 | I51: Order_ID present | J51: Order_ID is non-NULL and non-blank | L51: Order_ID = "NULL" or missing | M51: 2 rows | N51: → DELETE
H52: Reason_2 | I52: Price data present | J52: At least one price column has a numeric value | L52: Both Buy_Price AND Sell_Price = "NULL" | M52: 3 rows | N52: → DELETE
H53: Reason_3 | I53: Holdings non-negative | J53: Cumulative Curr_Hold ≥ 0 after applying this trade | L53: Curr_Hold < 0 (oversell detected) | M53: 53 rows | N53: → DELETE
H54: Reason_4 | I54: Quantity present | J54: Quantity is a valid non-NULL numeric value | L54: Quantity = "NULL" or blank | M54: 54 rows* | N54: → DELETE
H55: Decision | I55: Final verdict | J55: ALL 4 Reasons = "VALID" → "KEEP" | L55: ANY Reason = "INVALID" → "DELETE" | M55: 54 DELETE 149 KEEP | N55: Copied to Cleaned sheet
H63: BEFORE vs AFTER — REAL SAMPLE ROW COMPARISONS
H64: RAW DATA (issues present) | L64: ✔ AFTER CLEANING
H65: Order_ID | I65: Order_Type (Raw) | J65: Date (Raw) | K65: Decision | L65: Order_Type (Clean) | M65: Date (Clean) | N65: Issue Fixed / Reason
...

Sheet Cleaned Data
H1: 📈 STOCK MARKET PORTFOLIO TRACKER & RETURN ANALYZER
H6: Cleaned Data
H11: Order_ID | I11: Date | J11: Sector | K11: Stock_Name | L11: Buy_Price | M11: Sell_Price | N11: Quantity | O11: Order_Type | P11: Curr_holding | Q11: BP*Qty
H12: ORD1076 | I12: 45756 | J12: Paints | K12: ASIANPAINT | L12: 2464.09 | N12: 10 | O12: BUY | P12: =IF(J12=J13, P13 + IF(O12="BUY", N12, -N12), IF(O12="BUY", N12, -N12)) -> 35 | Q12: =IF(orderTable[[#This Row],[Buy_Price]]<>"",ROUND(IF(orderTable[[#This Row],[Order_Type]]="BUY",orderTable[[#This Row],[Buy_Price]]*orderTable[[#This Row],[Quantity]],""),2), "") -> 24640.9
H13: ORD1073 | I13: 45747 | J13: Paints | K13: ASIANPAINT | M13: 3284.04 | N13: 25 | O13: SELL | P13: =IF(J13=J14, P14 + IF(O13="BUY", N13, -N13), IF(O13="BUY", N13, -N13)) -> 25 | Q13: =IF(orderTable[[#This Row],[Buy_Price]]<>"",ROUND(IF(orderTable[[#This Row],[Order_Type]]="BUY",orderTable[[#This Row],[Buy_Price]]*orderTable[[#This Row],[Quantity]],""),2), "")
H14: ORD1166 | I14: 45706 | J14: Paints | K14: ASIANPAINT | L14: 1920.27 | N14: 50 | O14: BUY | P14: =IF(J14=J15, P15 + IF(O14="BUY", N14, -N14), IF(O14="BUY", N14, -N14)) -> 50 | Q14: =IF(orderTable[[#This Row],[Buy_Price]]<>"",ROUND(IF(orderTable[[#This Row],[Order_Type]]="BUY",orderTable[[#This Row],[Buy_Price]]*orderTable[[#This Row],[Quantity]],""),2), "") -> 96013.5
H15: ORD1186 | I15: 45831 | J15: Banking | K15: AXISBANK | L15: 2282.67 | N15: 25 | O15: BUY | P15: =IF(J15=J16, P16 + IF(O15="BUY", N15, -N15), IF(O15="BUY", N15, -N15)) -> 50 | Q15: =IF(orderTable[[#This Row],[Buy_Price]]<>"",ROUND(IF(orderTable[[#This Row],[Order_Type]]="BUY",orderTable[[#This Row],[Buy_Price]]*orderTable[[#This Row],[Quantity]],""),2), "") -> 57066.75
H16: ORD1011 | I16: 45829 | J16: Banking | K16: AXISBANK | L16: 1390.11 | N16: 20 | O16: BUY | P16: =IF(J16=J17, P17 + IF(O16="BUY", N16, -N16), IF(O16="BUY", N16, -N16)) -> 25 | Q16: =IF(orderTable[[#This Row],[Buy_Price]]<>"",ROUND(IF(orderTable[[#This Row],[Order_Type]]="BUY",orderTable[[#This Row],[Buy_Price]]*orderTable[[#This Row],[Quantity]],""),2), "") -> 27802.2
H17: ORD1122 | I17: 45800 | J17: Banking | K17: AXISBANK | M17: 1228.25 | N17: 25 | O17: SELL | P17: =IF(J17=J18, P18 + IF(O17="BUY", N17, -N17), IF(O17="BUY", N17, -N17)) -> 5 | Q17: =IF(orderTable[[#This Row],[Buy_Price]]<>"",ROUND(IF(orderTable[[#This Row],[Order_Type]]="BUY",orderTable[[#This Row],[Buy_Price]]*orderTable[[#This Row],[Quantity]],""),2), "")
H18: ORD1177 | I18: 45793 | J18: Banking | K18: AXISBANK | M18: 1644.42 | N18: 20 | O18: SELL | P18: =IF(J18=J19, P19 + IF(O18="BUY", N18, -N18), IF(O18="BUY", N18, -N18)) -> 30 | Q18: =IF(orderTable[[#This Row],[Buy_Price]]<>"",ROUND(IF(orderTable[[#This Row],[Order_Type]]="BUY",orderTable[[#This Row],[Buy_Price]]*orderTable[[#This Row],[Quantity]],""),2), "")
H19: ORD1127 | I19: 45748 | J19: Banking | K19: AXISBANK | M19: 3804.69 | N19: 50 | O19: SELL | P19: =IF(J19=J20, P20 + IF(O19="BUY", N19, -N19), IF(O19="BUY", N19, -N19)) -> 50 | Q19: =IF(orderTable[[#This Row],[Buy_Price]]<>"",ROUND(IF(orderTable[[#This Row],[Order_Type]]="BUY",orderTable[[#This Row],[Buy_Price]]*orderTable[[#This Row],[Quantity]],""),2), "")
H20: ORD1195 | I20: 45664 | J20: Banking | K20: AXISBANK | L20: 2410.7 | N20: 100 | O20: BUY | P20: =IF(J20=J21, P21 + IF(O20="BUY", N20, -N20), IF(O20="BUY", N20, -N20)) -> 100 | Q20: =IF(orderTable[[#This Row],[Buy_Price]]<>"",ROUND(IF(orderTable[[#This Row],[Order_Type]]="BUY",orderTable[[#This Row],[Buy_Price]]*orderTable[[#This Row],[Quantity]],""),2), "") -> 241070
H21: ORD1022 | I21: 45832 | J21: Finance | K21: BAJFINANCE | L21: 2428.95 | N21: 10 | O21: BUY | P21: =IF(J21=J22, P22 + IF(O21="BUY", N21, -N21), IF(O21="BUY", N21, -N21)) -> 280 | Q21: =IF(orderTable[[#This Row],[Buy_Price]]<>"",ROUND(IF(orderTable[[#This Row],[Order_Type]]="BUY",orderTable[[#This Row],[Buy_Price]]*orderTable[[#This Row],[Quantity]],""),2), "") -> 24289.5
H22: ORD1199 | I22: 45829 | J22: Finance | K22: BAJFINANCE | L22: 1451.96 | N22: 50 | O22: BUY | P22: =IF(J22=J23, P23 + IF(O22="BUY", N22, -N22), IF(O22="BUY", N22, -N22)) -> 270 | Q22: =IF(orderTable[[#This Row],[Buy_Price]]<>"",ROUND(IF(orderTable[[#This Row],[Order_Type]]="BUY",orderTable[[#This Row],[Buy_Price]]*orderTable[[#This Row],[Quantity]],""),2), "") -> 72598
H23: ORD1057 | I23: 45828 | J23: Finance | K23: BAJFINANCE | M23: 2448.55 | N23: 5 | O23: SELL | P23: =IF(J23=J24, P24 + IF(O23="BUY", N23, -N23), IF(O23="BUY", N23, -N23)) -> 220 | Q23: =IF(orderTable[[#This Row],[Buy_Price]]<>"",ROUND(IF(orderTable[[#This Row],[Order_Type]]="BUY",orderTable[[#This Row],[Buy_Price]]*orderTable[[#This Row],[Quantity]],""),2), "")
H24: ORD1078 | I24: 45828 | J24: Finance | K24: BAJFINANCE | L24: 1370.14 | N24: 10 | O24: BUY | P24: =IF(J24=J25, P25 + IF(O24="BUY", N24, -N24), IF(O24="BUY", N24, -N24)) -> 225 | Q24: =IF(orderTable[[#This Row],[Buy_Price]]<>"",ROUND(IF(orderTable[[#This Row],[Order_Type]]="BUY",orderTable[[#This Row],[Buy_Price]]*orderTable[[#This Row],[Quantity]],""),2), "") -> 13701.4
H25: ORD1091 | I25: 45814 | J25: Finance | K25: BAJFINANCE | M25: 3709.22 | N25: 100 | O25: SELL | P25: =IF(J25=J26, P26 + IF(O25="BUY", N25, -N25), IF(O25="BUY", N25, -N25)) -> 215 | Q25: =IF(orderTable[[#This Row],[Buy_Price]]<>"",ROUND(IF(orderTable[[#This Row],[Order_Type]]="BUY",orderTable[[#This Row],[Buy_Price]]*orderTable[[#This Row],[Quantity]],""),2), "")
H26: ORD1181 | I26: 45808 | J26: Finance | K26: BAJFINANCE | L26: 397.44 | N26: 50 | O26: BUY | P26: =IF(J26=J27, P27 + IF(O26="BUY", N26, -N26), IF(O26="BUY", N26, -N26)) -> 315 | Q26: =IF(orderTable[[#This Row],[Buy_Price]]<>"",ROUND(IF(orderTable[[#This Row],[Order_Type]]="BUY",orderTable[[#This Row],[Buy_Price]]*orderTable[[#This Row],[Quantity]],""),2), "") -> 19872
H27: ORD1018 | I27: 45807 | J27: Finance | K27: BAJFINANCE | M27: 2731.75 | N27: 75 | O27: SELL | P27: =IF(J27=J28, P28 + IF(O27="BUY", N27, -N27), IF(O27="BUY", N27, -N27)) -> 265 | Q27: =IF(orderTable[[#This Row],[Buy_Price]]<>"",ROUND(IF(orderTable[[#This Row],[Order_Type]]="BUY",orderTable[[#This Row],[Buy_Price]]*orderTable[[#This Row],[Quantity]],""),2), "")
H28: ORD1008 | I28: 45805 | J28: Finance | K28: BAJFINANCE | M28: 2894.7 | N28: 50 | O28: SELL | P28: =IF(J28=J29, P29 + IF(O28="BUY", N28, -N28), IF(O28="BUY", N28, -N28)) -> 340 | Q28: =IF(orderTable[[#This Row],[Buy_Price]]<>"",ROUND(IF(orderTable[[#This Row],[Order_Type]]="BUY",orderTable[[#This Row],[Buy_Price]]*orderTable[[#This Row],[Quantity]],""),2), "")
H29: ORD1030 | I29: 45798 | J29: Finance | K29: BAJFINANCE | L29: 580.11 | N29: 100 | O29: BUY | P29: =IF(J29=J30, P30 + IF(O29="BUY", N29, -N29), IF(O29="BUY", N29, -N29)) -> 390 | Q29: =IF(orderTable[[#This Row],[Buy_Price]]<>"",ROUND(IF(orderTable[[#This Row],[Order_Type]]="BUY",orderTable[[#This Row],[Buy_Price]]*orderTable[[#This Row],[Quantity]],""),2), "") -> 58011
H30: ORD1116 | I30: 45787 | J30: Finance | K30: BAJFINANCE | M30: 2554.22 | N30: 10 | O30: SELL | P30: =IF(J30=J31, P31 + IF(O30="BUY", N30, -N30), IF(O30="BUY", N30, -N30)) -> 290 | Q30: =IF(orderTable[[#This Row],[Buy_Price]]<>"",ROUND(IF(orderTable[[#This Row],[Order_Type]]="BUY",orderTable[[#This Row],[Buy_Price]]*orderTable[[#This Row],[Quantity]],""),2), "")
H31: ORD1124 | I31: 45772 | J31: Finance | K31: BAJFINANCE | L31: 2463.54 | N31: 100 | O31: BUY | P31: =IF(J31=J32, P32 + IF(O31="BUY", N31, -N31), IF(O31="BUY", N31, -N31)) -> 300 | Q31: =IF(orderTable[[#This Row],[Buy_Price]]<>"",ROUND(IF(orderTable[[#This Row],[Order_Type]]="BUY",orderTable[[#This Row],[Buy_Price]]*orderTable[[#This Row],[Quantity]],""),2), "") -> 246354
H32: ORD1101 | I32: 45769 | J32: Finance | K32: BAJFINANCE | L32: 1785.57 | N32: 25 | O32: BUY | P32: =IF(J32=J33, P33 + IF(O32="BUY", N32, -N32), IF(O32="BUY", N32, -N32)) -> 200 | Q32: =IF(orderTable[[#This Row],[Buy_Price]]<>"",ROUND(IF(orderTable[[#This Row],[Order_Type]]="BUY",orderTable[[#This Row],[Buy_Price]]*orderTable[[#This Row],[Quantity]],""),2), "") -> 44639.25
H33: ORD1098 | I33: 45765 | J33: Finance | K33: BAJFINANCE | M33: 1585.88 | N33: 20 | O33: SELL | P33: =IF(J33=J34, P34 + IF(O33="BUY", N33, -N33), IF(O33="BUY", N33, -N33)) -> 175 | Q33: =IF(orderTable[[#This Row],[Buy_Price]]<>"",ROUND(IF(orderTable[[#This Row],[Order_Type]]="BUY",orderTable[[#This Row],[Buy_Price]]*orderTable[[#This Row],[Quantity]],""),2), "")
H34: ORD1055 | I34: 45747 | J34: Finance | K34: BAJFINANCE | L34: 1844.71 | N34: 15 | O34: BUY | P34: =IF(J34=J35, P35 + IF(O34="BUY", N34, -N34), IF(O34="BUY", N34, -N34)) -> 195 | Q34: =IF(orderTable[[#This Row],[Buy_Price]]<>"",ROUND(IF(orderTable[[#This Row],[Order_Type]]="BUY",orderTable[[#This Row],[Buy_Price]]*orderTable[[#This Row],[Quantity]],""),2), "") -> 27670.65
H35: ORD1119 | I35: 45740 | J35: Finance | K35: BAJFINANCE | M35: 1912.79 | N35: 25 | O35: SELL | P35: =IF(J35=J36, P36 + IF(O35="BUY", N35, -N35), IF(O35="BUY", N35, -N35)) -> 180 | Q35: =IF(orderTable[[#This Row],[Buy_Price]]<>"",ROUND(IF(orderTable[[#This Row],[Order_Type]]="BUY",orderTable[[#This Row],[Buy_Price]]*orderTable[[#This Row],[Quantity]],""),2), "")
H36: ORD1129 | I36: 45728 | J36: Finance | K36: BAJFINANCE | L36: 791.66 | N36: 100 | O36: BUY | P36: =IF(J36=J37, P37 + IF(O36="BUY", N36, -N36), IF(O36="BUY", N36, -N36)) -> 205 | Q36: =IF(orderTable[[#This Row],[Buy_Price]]<>"",ROUND(IF(orderTable[[#This Row],[Order_Type]]="BUY",orderTable[[#This Row],[Buy_Price]]*orderTable[[#This Row],[Quantity]],""),2), "") -> 79166
H37: ORD1037 | I37: 45720 | J37: Finance | K37: BAJFINANCE | L37: 2573.23 | N37: 100 | O37: BUY | P37: =IF(J37=J38, P38 + IF(O37="BUY", N37, -N37), IF(O37="BUY", N37, -N37)) -> 105 | Q37: =IF(orderTable[[#This Row],[Buy_Price]]<>"",ROUND(IF(orderTable[[#This Row],[Order_Type]]="BUY",orderTable[[#This Row],[Buy_Price]]*orderTable[[#This Row],[Quantity]],""),2), "") -> 257323
H38: ORD1014 | I38: 45716 | J38: Finance | K38: BAJFINANCE | L38: 2443.46 | N38: 5 | O38: BUY | P38: =IF(J38=J39, P39 + IF(O38="BUY", N38, -N38), IF(O38="BUY", N38, -N38)) -> 5 | Q38: =IF(orderTable[[#This Row],[Buy_Price]]<>"",ROUND(IF(orderTable[[#This Row],[Order_Type]]="BUY",orderTable[[#This Row],[Buy_Price]]*orderTable[[#This Row],[Quantity]],""),2), "") -> 12217.3
H39: ORD1190 | I39: 45700 | J39: Finance | K39: BAJFINANCE | M39: 1931.04 | N39: 25 | O39: SELL | P39: =IF(J39=J40, P40 + IF(O39="BUY", N39, -N39), IF(O39="BUY", N39, -N39)) -> 0 | Q39: =IF(orderTable[[#This Row],[Buy_Price]]<>"",ROUND(IF(orderTable[[#This Row],[Order_Type]]="BUY",orderTable[[#This Row],[Buy_Price]]*orderTable[[#This Row],[Quantity]],""),2), "")
H40: ORD1023 | I40: 45686 | J40: Finance | K40: BAJFINANCE | M40: 2748.51 | N40: 50 | O40: SELL | P40: =IF(J40=J41, P41 + IF(O40="BUY", N40, -N40), IF(O40="BUY", N40, -N40)) -> 25 | Q40: =IF(orderTable[[#This Row],[Buy_Price]]<>"",ROUND(IF(orderTable[[#This Row],[Order_Type]]="BUY",orderTable[[#This Row],[Buy_Price]]*orderTable[[#This Row],[Quantity]],""),2), "")
H41: ORD1007 | I41: 45678 | J41: Finance | K41: BAJFINANCE | L41: 3409.94 | N41: 75 | O41: BUY | P41: =IF(J41=J42, P42 + IF(O41="BUY", N41, -N41), IF(O41="BUY", N41, -N41)) -> 75 | Q41: =IF(orderTable[[#This Row],[Buy_Price]]<>"",ROUND(IF(orderTable[[#This Row],[Order_Type]]="BUY",orderTable[[#This Row],[Buy_Price]]*orderTable[[#This Row],[Quantity]],""),2), "") -> 255745.5
H42: ORD1001 | I42: 45809 | J42: Banking | K42: ICICIBANK | L42: 2416.94 | N42: 10 | O42: BUY | P42: =IF(J42=J43, P43 + IF(O42="BUY", N42, -N42), IF(O42="BUY", N42, -N42)) -> 165 | Q42: =IF(orderTable[[#This Row],[Buy_Price]]<>"",ROUND(IF(orderTable[[#This Row],[Order_Type]]="BUY",orderTable[[#This Row],[Buy_Price]]*orderTable[[#This Row],[Quantity]],""),2), "") -> 24169.4
H43: ORD1110 | I43: 45802 | J43: Banking | K43: ICICIBANK | L43: 572.84 | N43: 10 | O43: BUY | P43: =IF(J43=J44, P44 + IF(O43="BUY", N43, -N43), IF(O43="BUY", N43, -N43)) -> 155 | Q43: =IF(orderTable[[#This Row],[Buy_Price]]<>"",ROUND(IF(orderTable[[#This Row],[Order_Type]]="BUY",orderTable[[#This Row],[Buy_Price]]*orderTable[[#This Row],[Quantity]],""),2), "") -> 5728.4
H44: ORD1161 | I44: 45788 | J44: Banking | K44: ICICIBANK | M44: 3572.63 | N44: 25 | O44: SELL | P44: =IF(J44=J45, P45 + IF(O44="BUY", N44, -N44), IF(O44="BUY", N44, -N44)) -> 145 | Q44: =IF(orderTable[[#This Row],[Buy_Price]]<>"",ROUND(IF(orderTable[[#This Row],[Order_Type]]="BUY",orderTable[[#This Row],[Buy_Price]]*orderTable[[#This Row],[Quantity]],""),2), "")
H45: ORD1068 | I45: 45763 | J45: Banking | K45: ICICIBANK | L45: 3046.43 | N45: 15 | O45: BUY | P45: =IF(J45=J46, P46 + IF(O45="BUY", N45, -N45), IF(O45="BUY", N45, -N45)) -> 170 | Q45: =IF(orderTable[[#This Row],[Buy_Price]]<>"",ROUND(IF(orderTable[[#This Row],[Order_Type]]="BUY",orderTable[[#This Row],[Buy_Price]]*orderTable[[#This Row],[Quantity]],""),2), "") -> 45696.45
H46: ORD1171 | I46: 45744 | J46: Banking | K46: ICICIBANK | L46: 1722.79 | N46: 25 | O46: BUY | P46: =IF(J46=J47, P47 + IF(O46="BUY", N46, -N46), IF(O46="BUY", N46, -N46)) -> 155 | Q46: =IF(orderTable[[#This Row],[Buy_Price]]<>"",ROUND(IF(orderTable[[#This Row],[Order_Type]]="BUY",orderTable[[#This Row],[Buy_Price]]*orderTable[[#This Row],[Quantity]],""),2), "") -> 43069.75
H47: ORD1097 | I47: 45742 | J47: Banking | K47: ICICIBANK | L47: 365.17 | N47: 75 | O47: BUY | P47: =IF(J47=J48, P48 + IF(O47="BUY", N47, -N47), IF(O47="BUY", N47, -N47)) -> 130 | Q47: =IF(orderTable[[#This Row],[Buy_Price]]<>"",ROUND(IF(orderTable[[#This Row],[Order_Type]]="BUY",orderTable[[#This Row],[Buy_Price]]*orderTable[[#This Row],[Quantity]],""),2), "") -> 27387.75
H48: ORD1187 | I48: 45737 | J48: Banking | K48: ICICIBANK | L48: 3176.4 | N48: 5 | O48: BUY | P48: =IF(J48=J49, P49 + IF(O48="BUY", N48, -N48), IF(O48="BUY", N48, -N48)) -> 55 | Q48: =IF(orderTable[[#This Row],[Buy_Price]]<>"",ROUND(IF(orderTable[[#This Row],[Order_Type]]="BUY",orderTable[[#This Row],[Buy_Price]]*orderTable[[#This Row],[Quantity]],""),2), "") -> 15882
...

Sheet My Holdings
I1: 📈 STOCK MARKET PORTFOLIO TRACKER & RETURN ANALYZER
I6: My Holdings | T6: Live Stock DATA
I15: Stock_Name | J15: Sector | K15: Quantity | L15: Avg_Buy_Price | M15: Total_Investment | N15: Current_Price | O15: Market_Value | P15: Profit/Loss | Q15: Return % | T15: Stock_Name | U15: Ticker symbol | V15: Current_Price
I16: {=_FV(Table5[[#This Row],[Stock_Name]],"Ticker symbol",TRUE)} -> ASIANPAINT | J16: =_xlfn.XLOOKUP(I16,orderTable[Stock_Name],orderTable[Sector],"Undefined",0,1) -> Paints | K16: =SUMIFS(orderTable[Quantity],orderTable[Stock_Name],'My Holdings'!I16,orderTable[Order_Type],"BUY") - SUMIFS(orderTable[Quantity],orderTable[Stock_Name],'My Holdings'!I16,orderTable[Order_Type],"SELL") -> 35 | L16: =ROUND(SUMIFS(orderTable[BP*Qty],orderTable[Stock_Name],'My Holdings'!I16,orderTable[Order_Type],"BUY") / SUMIFS(orderTable[Quantity],orderTable[Stock_Name],'My Holdings'!I16,orderTable[Order_Type],"BUY"),2) -> 2010.91 | M16: =L16*K16 -> 70381.85 | N16: =_xlfn.XLOOKUP(I16,Table5[Ticker symbol],Table5[Current_Price],0,0,1) -> 2671.9 | O16: =N16*K16 -> 93516.5 | P16: =O16-M16 -> 23134.65 | Q16: =IF(M16<>0,P16/M16,0) -> 0.32870193 | T16: #VALUE! | U16: {=_FV(Table5[[#This Row],[Stock_Name]],"Ticker symbol",TRUE)} -> ASIANPAINT | V16: {=_FV(T16,"Price")} -> 2671.9
I17: {=_FV(Table5[[#This Row],[Stock_Name]],"Ticker symbol",TRUE)} -> AXISBANK | J17: =_xlfn.XLOOKUP(I17,orderTable[Stock_Name],orderTable[Sector],"Undefined",0,1) -> Banking | K17: =SUMIFS(orderTable[Quantity],orderTable[Stock_Name],'My Holdings'!I17,orderTable[Order_Type],"BUY") - SUMIFS(orderTable[Quantity],orderTable[Stock_Name],'My Holdings'!I17,orderTable[Order_Type],"SELL") -> 50 | L17: =ROUND(SUMIFS(orderTable[BP*Qty],orderTable[Stock_Name],'My Holdings'!I17,orderTable[Order_Type],"BUY") / SUMIFS(orderTable[Quantity],orderTable[Stock_Name],'My Holdings'!I17,orderTable[Order_Type],"BUY"),2) -> 2247.85 | M17: =L17*K17 -> 112392.5 | N17: =_xlfn.XLOOKUP(I17,Table5[Ticker symbol],Table5[Current_Price],0,0,1) -> 1304.1 | O17: =N17*K17 -> 65205 | P17: =O17-M17 -> -47187.5 | Q17: =IF(M17<>0,P17/M17,0) -> -0.41984563 | T17: #VALUE! | U17: {=_FV(Table5[[#This Row],[Stock_Name]],"Ticker symbol",TRUE)} -> AXISBANK | V17: {=_FV(T17,"Price")} -> 1304.1
I18: {=_FV(Table5[[#This Row],[Stock_Name]],"Ticker symbol",TRUE)} -> BAJFINANCE | J18: =_xlfn.XLOOKUP(I18,orderTable[Stock_Name],orderTable[Sector],"Undefined",0,1) -> Finance | K18: =SUMIFS(orderTable[Quantity],orderTable[Stock_Name],'My Holdings'!I18,orderTable[Order_Type],"BUY") - SUMIFS(orderTable[Quantity],orderTable[Stock_Name],'My Holdings'!I18,orderTable[Order_Type],"SELL") -> 280 | L18: =ROUND(SUMIFS(orderTable[BP*Qty],orderTable[Stock_Name],'My Holdings'!I18,orderTable[Order_Type],"BUY") / SUMIFS(orderTable[Quantity],orderTable[Stock_Name],'My Holdings'!I18,orderTable[Order_Type],"BUY"),2) -> 1736.86 | M18: =L18*K18 -> 486320.8 | N18: =_xlfn.XLOOKUP(I18,Table5[Ticker symbol],Table5[Current_Price],0,0,1) -> 931.15 | O18: =N18*K18 -> 260722 | P18: =O18-M18 -> -225598.8 | Q18: =IF(M18<>0,P18/M18,0) -> -0.46388886 | T18: #VALUE! | U18: {=_FV(Table5[[#This Row],[Stock_Name]],"Ticker symbol",TRUE)} -> BAJFINANCE | V18: {=_FV(T18,"Price")} -> 931.15
I19: {=_FV(Table5[[#This Row],[Stock_Name]],"Ticker symbol",TRUE)} -> ICICIBANK | J19: =_xlfn.XLOOKUP(I19,orderTable[Stock_Name],orderTable[Sector],"Undefined",0,1) -> Banking | K19: =SUMIFS(orderTable[Quantity],orderTable[Stock_Name],'My Holdings'!I19,orderTable[Order_Type],"BUY") - SUMIFS(orderTable[Quantity],orderTable[Stock_Name],'My Holdings'!I19,orderTable[Order_Type],"SELL") -> 165 | L19: =ROUND(SUMIFS(orderTable[BP*Qty],orderTable[Stock_Name],'My Holdings'!I19,orderTable[Order_Type],"BUY") / SUMIFS(orderTable[Quantity],orderTable[Stock_Name],'My Holdings'!I19,orderTable[Order_Type],"BUY"),2) -> 852.28 | M19: =L19*K19 -> 140626.2 | N19: =_xlfn.XLOOKUP(I19,Table5[Ticker symbol],Table5[Current_Price],0,0,1) -> 1272.7 | O19: =N19*K19 -> 209995.5 | P19: =O19-M19 -> 69369.3 | Q19: =IF(M19<>0,P19/M19,0) -> 0.49328859 | T19: #VALUE! | U19: {=_FV(Table5[[#This Row],[Stock_Name]],"Ticker symbol",TRUE)} -> ICICIBANK | V19: {=_FV(T19,"Price")} -> 1272.7
I20: {=_FV(Table5[[#This Row],[Stock_Name]],"Ticker symbol",TRUE)} -> INFY | J20: =_xlfn.XLOOKUP(I20,orderTable[Stock_Name],orderTable[Sector],"Undefined",0,1) -> IT | K20: =SUMIFS(orderTable[Quantity],orderTable[Stock_Name],'My Holdings'!I20,orderTable[Order_Type],"BUY") - SUMIFS(orderTable[Quantity],orderTable[Stock_Name],'My Holdings'!I20,orderTable[Order_Type],"SELL") -> 275 | L20: =ROUND(SUMIFS(orderTable[BP*Qty],orderTable[Stock_Name],'My Holdings'!I20,orderTable[Order_Type],"BUY") / SUMIFS(orderTable[Quantity],orderTable[Stock_Name],'My Holdings'!I20,orderTable[Order_Type],"BUY"),2) -> 1028.39 | M20: =L20*K20 -> 282807.25 | N20: =_xlfn.XLOOKUP(I20,Table5[Ticker symbol],Table5[Current_Price],0,0,1) -> 1159.9 | O20: =N20*K20 -> 318972.5 | P20: =O20-M20 -> 36165.25 | Q20: =IF(M20<>0,P20/M20,0) -> 0.1278795 | T20: #VALUE! | U20: {=_FV(Table5[[#This Row],[Stock_Name]],"Ticker symbol",TRUE)} -> INFY | V20: {=_FV(T20,"Price")} -> 1159.9
I21: {=_FV(Table5[[#This Row],[Stock_Name]],"Ticker symbol",TRUE)} -> ITC | J21: =_xlfn.XLOOKUP(I21,orderTable[Stock_Name],orderTable[Sector],"Undefined",0,1) -> FMCG | K21: =SUMIFS(orderTable[Quantity],orderTable[Stock_Name],'My Holdings'!I21,orderTable[Order_Type],"BUY") - SUMIFS(orderTable[Quantity],orderTable[Stock_Name],'My Holdings'!I21,orderTable[Order_Type],"SELL") -> 375 | L21: =ROUND(SUMIFS(orderTable[BP*Qty],orderTable[Stock_Name],'My Holdings'!I21,orderTable[Order_Type],"BUY") / SUMIFS(orderTable[Quantity],orderTable[Stock_Name],'My Holdings'!I21,orderTable[Order_Type],"BUY"),2) -> 1402.64 | M21: =L21*K21 -> 525990 | N21: =_xlfn.XLOOKUP(I21,Table5[Ticker symbol],Table5[Current_Price],0,0,1) -> 291.95 | O21: =N21*K21 -> 109481.25 | P21: =O21-M21 -> -416508.75 | Q21: =IF(M21<>0,P21/M21,0) -> -0.79185678 | T21: #VALUE! | U21: {=_FV(Table5[[#This Row],[Stock_Name]],"Ticker symbol",TRUE)} -> ITC | V21: {=_FV(T21,"Price")} -> 291.95
I22: {=_FV(Table5[[#This Row],[Stock_Name]],"Ticker symbol",TRUE)} -> KOTAKBANK | J22: =_xlfn.XLOOKUP(I22,orderTable[Stock_Name],orderTable[Sector],"Undefined",0,1) -> Banking | K22: =SUMIFS(orderTable[Quantity],orderTable[Stock_Name],'My Holdings'!I22,orderTable[Order_Type],"BUY") - SUMIFS(orderTable[Quantity],orderTable[Stock_Name],'My Holdings'!I22,orderTable[Order_Type],"SELL") -> 20 | L22: =ROUND(SUMIFS(orderTable[BP*Qty],orderTable[Stock_Name],'My Holdings'!I22,orderTable[Order_Type],"BUY") / SUMIFS(orderTable[Quantity],orderTable[Stock_Name],'My Holdings'!I22,orderTable[Order_Type],"BUY"),2) -> 1534.72 | M22: =L22*K22 -> 30694.4 | N22: =_xlfn.XLOOKUP(I22,Table5[Ticker symbol],Table5[Current_Price],0,0,1) -> 388.7 | O22: =N22*K22 -> 7774 | P22: =O22-M22 -> -22920.4 | Q22: =IF(M22<>0,P22/M22,0) -> -0.74672905 | T22: #VALUE! | U22: {=_FV(Table5[[#This Row],[Stock_Name]],"Ticker symbol",TRUE)} -> KOTAKBANK | V22: {=_FV(T22,"Price")} -> 388.7
I23: {=_FV(Table5[[#This Row],[Stock_Name]],"Ticker symbol",TRUE)} -> LT | J23: =_xlfn.XLOOKUP(I23,orderTable[Stock_Name],orderTable[Sector],"Undefined",0,1) -> Infrastructure | K23: =SUMIFS(orderTable[Quantity],orderTable[Stock_Name],'My Holdings'!I23,orderTable[Order_Type],"BUY") - SUMIFS(orderTable[Quantity],orderTable[Stock_Name],'My Holdings'!I23,orderTable[Order_Type],"SELL") -> 265 | L23: =ROUND(SUMIFS(orderTable[BP*Qty],orderTable[Stock_Name],'My Holdings'!I23,orderTable[Order_Type],"BUY") / SUMIFS(orderTable[Quantity],orderTable[Stock_Name],'My Holdings'!I23,orderTable[Order_Type],"BUY"),2) -> 1358.88 | M23: =L23*K23 -> 360103.2 | N23: =_xlfn.XLOOKUP(I23,Table5[Ticker symbol],Table5[Current_Price],0,0,1) -> 4047.5 | O23: =N23*K23 -> 1072587.5 | P23: =O23-M23 -> 712484.3 | Q23: =IF(M23<>0,P23/M23,0) -> 1.9785559 | T23: #VALUE! | U23: {=_FV(Table5[[#This Row],[Stock_Name]],"Ticker symbol",TRUE)} -> LT | V23: {=_FV(T23,"Price")} -> 4047.5
